Workbook

Sheet Summary
A1: Melrose Industries (MRO.L): equity research model
A2: Rohan Sharma, 8 Oct 2026. Student project for learning; not investment advice.
A4: Recommendation | B4: =IF(Scenarios!B22>=0.15,"BUY",IF(Scenarios!B22<=-0.1,"SELL","HOLD")) -> BUY | C4: Buy if fair value is 15%+ above the price; sell if 10%+ below
A6: Share price (7 Oct 2026) | B6: =Inputs!$B$5 -> 450
A7: Fair value (probability-weighted) | B7: =Scenarios!B21 -> 608.77724
A8: Upside | B8: =Scenarios!B22 -> 0.35283831
A9: Market capitalisation (£m) | B9: =Inputs!$B$7 -> 5607
A10: Enterprise value incl. leases (£m) | B10: =Inputs!$B$11 -> 7478
A11: P/E 2026E (consensus EPS) | B11: =Comps!G11 -> 12.857143
A12: Peer median P/E 2026E | B12: =Comps!G10 -> 31.564299
A13: P/E 2026E on EPS excluding non-cash VC | B13: =Comps!G13 -> 37.494985
A14: FCF yield, 2026 guidance mid-point | B14: =Inputs!$B$26/Inputs!$B$7 -> 0.031210986
A15: FCF yield on the 2029 target (at US$1.37) | B15: =Inputs!$B$36/Inputs!$B$7 -> 0.098020332
A16: WACC | B16: =Inputs!$B$71 -> 0.09355599
A18: Scenario | B18: Value | C18: Upside | D18: Probability | E18: 2029 FCF (£m) | F18: % of 2029 target
A19: Bear | B19: =Scenarios!B15 -> 363.04557 | C19: =Scenarios!B16 -> -0.19323206 | D19: =Scenarios!B11 -> 0.25 | E19: =Scenarios!B17 -> 277.08268 | F19: =Scenarios!B18 -> 0.50415335
A20: Base | B20: =Scenarios!C15 -> 623.3794 | C20: =Scenarios!C16 -> 0.38528755 | D20: =Scenarios!C11 -> 0.5 | E20: =Scenarios!C17 -> 485.92614 | F20: =Scenarios!C18 -> 0.88414508
A21: Bull | B21: =Scenarios!D15 -> 825.30459 | C21: =Scenarios!D16 -> 0.83401021 | D21: =Scenarios!D11 -> 0.25 | E21: =Scenarios!D17 -> 614.48232 | F21: =Scenarios!D18 -> 1.1180537
A23: Valuation range (football field) | B23: Low (p) | C23: High (p) | D23: Basis
A24: 52-week trading range | B24: =Inputs!$B$12 -> 409.9 | C24: =Inputs!$B$13 -> 682.6 | D24: lse.co.uk
A25: Analyst price targets | B25: =Inputs!$B$17 -> 450 | C25: =Inputs!$B$18 -> 825 | D25: 15 analysts, 7 Oct 2026
A26: Senior plc takeover multiple (15.2x EBITDA) | B26: =Comps!G22 -> 402.58427 | C26: =Comps!G23 -> 797.83307 | D26: Low: VC worth nothing. High: VC worth full value
A27: DCF, base case (WACC +/-0.5pt, growth +/-0.5pt) | B27: =MIN(Sensitivity!C6:E8) -> 539.09808 | C27: =MAX(Sensitivity!C6:E8) -> 735.71958 | D27: Sensitivity sheet
A28: DCF, bear to bull | B28: =Scenarios!B15 -> 363.04557 | C28: =Scenarios!D15 -> 825.30459 | D28: Scenarios sheet
A30: How to use: change the yellow levers on Scenarios or any blue input on Inputs; every value recalculates.
A31: Colour code: blue = typed-in data, black = formula, green = link to another sheet, yellow = key judgement.
A32: The key judgement is how fast non-cash variable consideration (VC) turns into cash: see DCF row 32.

Sheet Inputs
A1: Inputs and sources
A2: Blue = typed-in data with its source. Black = formula. £m unless stated.
A3: Item | B3: Value | C3: Unit | D3: Source / reasoning
A4: Market data
A5: Share price | B5: 450 | C5: p | D5: LSE closing price, 7 Oct 2026 (lse.co.uk)
A6: Shares in issue | B6: 1246 | C6: m | D6: H1 2026 results (31 Jul 2026): excludes treasury shares, 30 Jun 2026
A7: Market capitalisation | B7: =B5*B6/100 -> 5607 | C7: £m | D7: Formula
A8: Net debt, 30 Jun 2026 | B8: 1530 | C8: £m | D8: H1 2026 results; excludes lease liabilities
A9: Lease liabilities | B9: 330 | C9: £m | D9: FY2025 results, 31 Dec 2025 (£31m current + £299m non-current)
A10: Net pension deficit, 30 Jun 2026 | B10: 11 | C10: £m | D10: H1 2026 results
A11: Enterprise value incl. leases | B11: =B7+B8+B9+B10 -> 7478 | C11: £m | D11: Formula: pairs with EBITDA, which adds back lease depreciation
A12: 52-week low | B12: 409.9 | C12: p | D12: 31 Jul 2026, H1 results day (lse.co.uk)
A13: 52-week high | B13: 682.6 | C13: p | D13: 19 Feb 2026, before FY2025 results (lse.co.uk)
A14: Consensus adjusted EPS 2026E | B14: 35 | C14: p | D14: S&P Global consensus via stockanalysis.com, 7 Oct 2026, 14-15 analysts
A15: Consensus adjusted EPS 2027E | B15: 45 | C15: p | D15: As above
A16: Analyst price target, average | B16: 663 | C16: p | D16: As above (15 analysts: 10 buy, 3 hold, 2 sell)
A17: Analyst price target, low | B17: 450 | C17: p | D17: As above
A18: Analyst price target, high | B18: 825 | C18: p | D18: As above
A19: FY2026 guidance mid-points (excludes Garden Grove; at US$1.37/£)
A20: Engines revenue | B20: 1750 | C20: £m | D20: FY2025 results (27 Feb 2026): £1,700-1,800m; reaffirmed 31 Jul 2026
A21: Engines adjusted operating profit | B21: 580 | C21: £m | D21: Guidance £565-595m
A22: Airframes revenue | B22: 2100 | C22: £m | D22: Guidance £2,050-2,150m
A23: Airframes adjusted operating profit | B23: 180 | C23: £m | D23: Guidance £170-190m
A24: Group adjusted operating profit | B24: 725 | C24: £m | D24: Guidance £700-750m
A25: Variable consideration (non-cash RRSP profit) | B25: 360 | C25: £m | D25: Guidance £340-380m, depending on engine build rates
A26: Free cash flow after interest and tax | B26: 175 | C26: £m | D26: Guidance £150-200m, including a £30-50m factoring inflow
A27: Central costs (implied) | B27: =B21+B23-B24 -> 35 | C27: £m | D27: Formula: divisions less group
A28: 2029 targets (at US$1.25/£)
A29: Revenue | B29: 5000 | C29: £m | D29: FY2025 results
A30: Adjusted operating profit | B30: 1200 | C30: £m | D30: FY2025 results: '£1.2+ billion'
A31: Free cash flow after interest and tax | B31: 600 | C31: £m | D31: FY2025 results; reaffirmed in H1 2026 results
A32: Profit change per 1 cent move in US$ | B32: 0.007 | C32: % | D32: H1 2026 results: 1 cent = £5m (0.7%) of adjusted operating profit
A33: Exchange rate in 2026 guidance | B33: 1.37 | C33: US$/£ | D33: FY2025 and H1 2026 results
A34: Exchange rate in 2029 targets | B34: 1.25 | C34: US$/£ | D34: FY2025 results
A35: Restates targets at the guidance rate | B35: =1-B32*(B33-B34)*100 -> 0.916 | C35: x | D35: Formula: a weaker dollar shrinks sterling profit
A36: 2029 FCF target at US$1.37 | B36: =B31*B35 -> 549.6 | C36: £m | D36: Formula: the like-for-like yardstick for this model
A37: Garden Grove (US transparencies plant, chemical tank incident May 2026)
A38: Lost revenue in 2026 | B38: 46 | C38: £m | D38: H1 actual £16m + H2 estimate £30m: about £6m a month at half capacity; full restart slipped past the 28 Sep target
A39: Lost adjusted operating profit in 2026 | B39: 39 | C39: £m | D39: H1 actual £9m + H2 estimate £30m
A40: H1 2026 actuals (the first half is already in the 30 Jun net debt)
...

Sheet Scenarios
A1: Scenario levers
A2: Yellow = the judgement calls that drive the valuation.
A3: Driver | B3: Bear | C3: Base | D3: Bull | E3: Why
A4: Engines revenue growth, 2027-29 | B4: 0.05 | C4: 0.08 | D4: 0.1 | E4: Management: high single-digit growth a year to 2029
A5: Engines margin reached by 2029 | B5: 0.32 | C5: 0.35 | D5: 0.37 | E5: Management: mid-to-high 30s%. 2025 actual 31.9%; 2026 guidance 33.1%
A6: Airframes revenue growth, 2027-29 | B6: 0.03 | C6: 0.05 | D6: 0.065 | E6: Management: mid single-digit growth a year to 2029
A7: Airframes margin reached by 2029 | B7: 0.085 | C7: 0.11 | D7: 0.125 | E7: Management: low teens. 2025 actual 8.0%; 2026 guidance 8.6%
A8: Non-cash VC as % of Engines revenue, 2029 | B8: 0.16 | C8: 0.11 | D8: 0.09 | E8: 2026 guidance: 20.6% (£360m of £1,750m). Lower = profit turning into cash faster
A9: Non-cash VC as % of Engines revenue, 2035 | B9: 0.08 | C9: 0.05 | D9: 0.025 | E9: Keeps falling as aftermarket cash from older engines catches up
A10: Remaining Garden Grove cash cost (£m) | B10: 250 | C10: 120 | D10: 60 | E10: Base: H2 exceptional costs £25-30m + compensation fund up to $100m (~£75m) + ~£15m legal. Bull: insurance pays half. Bear: lawsuits double it
A11: Probability | B11: 0.25 | C11: 0.5 | D11: 0.25 | E11: Base case twice as likely as either tail
A12: Probabilities sum to | B12: =SUM(B11:D11) -> 1
A14: Results
A15: Value per share | B15: =DCF_Bear!$D$62 -> 363.04557 | C15: =DCF_Base!$D$62 -> 623.3794 | D15: =DCF_Bull!$D$62 -> 825.30459
A16: Upside / (downside) vs share price | B16: =DCF_Bear!$D$63 -> -0.19323206 | C16: =DCF_Base!$D$63 -> 0.38528755 | D16: =DCF_Bull!$D$63 -> 0.83401021
A17: 2029 FCF after interest and tax (£m) | B17: =DCF_Bear!$G$67 -> 277.08268 | C17: =DCF_Base!$G$67 -> 485.92614 | D17: =DCF_Bull!$G$67 -> 614.48232
A18: % of management's 2029 FCF target | B18: =DCF_Bear!$G$69 -> 0.50415335 | C18: =DCF_Base!$G$69 -> 0.88414508 | D18: =DCF_Bull!$G$69 -> 1.1180537
A19: Enterprise value (£m) | B19: =DCF_Bear!$D$56 -> 6314.5479 | C19: =DCF_Base!$D$56 -> 9428.3073 | D19: =DCF_Bull!$D$56 -> 11884.295
A21: Probability-weighted value per share | B21: =SUMPRODUCT(B11:D11,B15:D15) -> 608.77724
A22: Upside / (downside) vs share price | B22: =B21/Inputs!$B$5-1 -> 0.35283831

Sheet DCF_Base
A1: Discounted cash flow: base case
A2: £m unless stated. Forecasts at US$1.37/£, the 2026 guidance rate. Valued at 30 Jun 2026, the date of the latest net debt.
A4: Year | B4: Note | C4: 2025A | D4: 2026E | E4: 2027E | F4: 2028E | G4: 2029E | H4: 2030E | I4: 2031E | J4: 2032E | K4: 2033E | L4: 2034E | M4: 2035E
A5: Year (number) | C5: 2025 | D5: 2026 | E5: 2027 | F5: 2028 | G5: 2029 | H5: 2030 | I5: 2031 | J5: 2032 | K5: 2033 | L5: 2034 | M5: 2035
A6: Years after 2029 | D6: =MAX(0,D5-2029) -> 0 | E6: =MAX(0,E5-2029) -> 0 | F6: =MAX(0,F5-2029) -> 0 | G6: =MAX(0,G5-2029) -> 0 | H6: =MAX(0,H5-2029) -> 1 | I6: =MAX(0,I5-2029) -> 2 | J6: =MAX(0,J5-2029) -> 3 | K6: =MAX(0,K5-2029) -> 4 | ... M6: =MAX(0,M5-2029) -> 6
A7: Progress to 2029 levels | B7: 0 in 2026, 1 by 2029 | D7: =MIN(MAX(D5-2026,0),3)/3 -> 0 | E7: =MIN(MAX(E5-2026,0),3)/3 -> 0.33333333 | F7: =MIN(MAX(F5-2026,0),3)/3 -> 0.66666667 | G7: =MIN(MAX(G5-2026,0),3)/3 -> 1 | H7: =MIN(MAX(H5-2026,0),3)/3 -> 1 | I7: =MIN(MAX(I5-2026,0),3)/3 -> 1 | J7: =MIN(MAX(J5-2026,0),3)/3 -> 1 | K7: =MIN(MAX(K5-2026,0),3)/3 -> 1 | ... M7: =MIN(MAX(M5-2026,0),3)/3 -> 1
A8: Discount period (years) | B8: From 30 Jun 2026, mid-period | D8: 0.25 | E8: =E5-2026 -> 1 | F8: =F5-2026 -> 2 | G8: =G5-2026 -> 3 | H8: =H5-2026 -> 4 | I8: =I5-2026 -> 5 | J8: =J5-2026 -> 6 | K8: =K5-2026 -> 7 | L8: =L5-2026 -> 8 | M8: =M5-2026 -> 9
A10: Engines revenue growth | B10: 2027-29 lever, then fades | D10: =D11/C11-1 -> 0.072303922 | E10: =Scenarios!$C$4 -> 0.08 | F10: =Scenarios!$C$4 -> 0.08 | G10: =Scenarios!$C$4 -> 0.08 | H10: =Scenarios!$C$4+(Inputs!$B$54-Scenarios!$C$4)*H6/6 -> 0.070833333 | I10: =Scenarios!$C$4+(Inputs!$B$54-Scenarios!$C$4)*I6/6 -> 0.061666667 | J10: =Scenarios!$C$4+(Inputs!$B$54-Scenarios!$C$4)*J6/6 -> 0.0525 | K10: =Scenarios!$C$4+(Inputs!$B$54-Scenarios!$C$4)*K6/6 -> 0.043333333 | L10: =Scenarios!$C$4+(Inputs!$B$54-Scenarios!$C$4)*L6/6 -> 0.034166667 | M10: =Scenarios!$C$4+(Inputs!$B$54-Scenarios!$C$4)*M6/6 -> 0.025
A11: Engines revenue | B11: 2026 = guidance mid-point | C11: 1632 | D11: =Inputs!$B$20 -> 1750 | E11: =D11*(1+E10) -> 1890 | F11: =E11*(1+F10) -> 2041.2 | G11: =F11*(1+G10) -> 2204.496 | H11: =G11*(1+H10) -> 2360.6478 | I11: =H11*(1+I10) -> 2506.2211 | J11: =I11*(1+J10) -> 2637.7977 | K11: =J11*(1+K10) -> 2752.1023 | L11: =K11*(1+L10) -> 2846.1324 | M11: =L11*(1+M10) -> 2917.2857
A12: Airframes revenue growth | B12: 2027-29 lever, then fades | D12: =D13/C13-1 -> 0.073071027 | E12: =Scenarios!$C$6 -> 0.05 | F12: =Scenarios!$C$6 -> 0.05 | G12: =Scenarios!$C$6 -> 0.05 | H12: =Scenarios!$C$6+(Inputs!$B$54-Scenarios!$C$6)*H6/6 -> 0.045833333 | I12: =Scenarios!$C$6+(Inputs!$B$54-Scenarios!$C$6)*I6/6 -> 0.041666667 | J12: =Scenarios!$C$6+(Inputs!$B$54-Scenarios!$C$6)*J6/6 -> 0.0375 | K12: =Scenarios!$C$6+(Inputs!$B$54-Scenarios!$C$6)*K6/6 -> 0.033333333 | L12: =Scenarios!$C$6+(Inputs!$B$54-Scenarios!$C$6)*L6/6 -> 0.029166667 | M12: =Scenarios!$C$6+(Inputs!$B$54-Scenarios!$C$6)*M6/6 -> 0.025
A13: Airframes revenue (before Garden Grove) | B13: 2026 = guidance | C13: 1957 | D13: =Inputs!$B$22 -> 2100 | E13: =D13*(1+E12) -> 2205 | F13: =E13*(1+F12) -> 2315.25 | G13: =F13*(1+G12) -> 2431.0125 | H13: =G13*(1+H12) -> 2542.4339 | I13: =H13*(1+I12) -> 2648.3687 | J13: =I13*(1+J12) -> 2747.6825 | K13: =J13*(1+K12) -> 2839.2719 | L13: =K13*(1+L12) -> 2922.084 | M13: =L13*(1+M12) -> 2995.1361
A14: Garden Grove lost revenue | B14: 2026 only | C14: 0 | D14: =-Inputs!$B$38 -> -46 | E14: 0 | F14: 0 | G14: 0 | H14: 0 | I14: 0 | J14: 0 | K14: 0 | L14: 0 | M14: 0
A15: Group revenue | C15: =C11+C13+C14 -> 3589 | D15: =D11+D13+D14 -> 3804 | E15: =E11+E13+E14 -> 4095 | F15: =F11+F13+F14 -> 4356.45 | G15: =G11+G13+G14 -> 4635.5085 | H15: =H11+H13+H14 -> 4903.0817 | I15: =I11+I13+I14 -> 5154.5897 | J15: =J11+J13+J14 -> 5385.4802 | ... M15: =M11+M13+M14 -> 5912.4218
A16: Revenue growth | D16: =D15/C15-1 -> 0.059905266 | E16: =E15/D15-1 -> 0.076498423 | F16: =F15/E15-1 -> 0.063846154 | G16: =G15/F15-1 -> 0.064056399 | H16: =H15/G15-1 -> 0.057722514 | I16: =I15/H15-1 -> 0.051295908 | J16: =J15/I15-1 -> 0.044793173 | K16: =K15/J15-1 -> 0.038231314 | ... M16: =M15/L15-1 -> 0.025
A18: Engines margin | B18: Straight line to the 2029 lever | C18: =C19/C11 -> 0.31862745 | D18: =Inputs!$B$21/Inputs!$B$20 -> 0.33142857 | E18: =$D18+(Scenarios!$C$5-$D18)*E7 -> 0.33761905 | F18: =$D18+(Scenarios!$C$5-$D18)*F7 -> 0.34380952 | G18: =$D18+(Scenarios!$C$5-$D18)*G7 -> 0.35 | H18: =$D18+(Scenarios!$C$5-$D18)*H7 -> 0.35 | I18: =$D18+(Scenarios!$C$5-$D18)*I7 -> 0.35 | J18: =$D18+(Scenarios!$C$5-$D18)*J7 -> 0.35 | K18: =$D18+(Scenarios!$C$5-$D18)*K7 -> 0.35 | L18: =$D18+(Scenarios!$C$5-$D18)*L7 -> 0.35 | M18: =$D18+(Scenarios!$C$5-$D18)*M7 -> 0.35
A19: Engines adjusted operating profit | C19: 520 | D19: =D11*D18 -> 580 | E19: =E11*E18 -> 638.1 | F19: =F11*F18 -> 701.784 | G19: =G11*G18 -> 771.5736 | H19: =H11*H18 -> 826.22673 | I19: =I11*I18 -> 877.17738 | J19: =J11*J18 -> 923.22919 | K19: =K11*K18 -> 963.23579 | ... M19: =M11*M18 -> 1021.05
A20: Airframes margin | B20: Straight line to the 2029 lever | C20: =C21/C13 -> 0.079713848 | D20: =Inputs!$B$23/Inputs!$B$22 -> 0.085714286 | E20: =$D20+(Scenarios!$C$7-$D20)*E7 -> 0.093809524 | F20: =$D20+(Scenarios!$C$7-$D20)*F7 -> 0.10190476 | G20: =$D20+(Scenarios!$C$7-$D20)*G7 -> 0.11 | H20: =$D20+(Scenarios!$C$7-$D20)*H7 -> 0.11 | I20: =$D20+(Scenarios!$C$7-$D20)*I7 -> 0.11 | J20: =$D20+(Scenarios!$C$7-$D20)*J7 -> 0.11 | K20: =$D20+(Scenarios!$C$7-$D20)*K7 -> 0.11 | L20: =$D20+(Scenarios!$C$7-$D20)*L7 -> 0.11 | M20: =$D20+(Scenarios!$C$7-$D20)*M7 -> 0.11
A21: Airframes adjusted operating profit | C21: 156 | D21: =D13*D20 -> 180 | E21: =E13*E20 -> 206.85 | F21: =F13*F20 -> 235.935 | G21: =G13*G20 -> 267.41138 | H21: =H13*H20 -> 279.66773 | I21: =I13*I20 -> 291.32055 | J21: =J13*J20 -> 302.24507 | K21: =K13*K20 -> 312.31991 | ... M21: =M13*M20 -> 329.46497
A22: Garden Grove lost profit | B22: 2026 only | C22: 0 | D22: =-Inputs!$B$39 -> -39 | E22: 0 | F22: 0 | G22: 0 | H22: 0 | I22: 0 | J22: 0 | K22: 0 | L22: 0 | M22: 0
A23: Central costs | B23: Grow with inflation | C23: -29 | D23: =-Inputs!$B$27 -> -35 | E23: =D23*(1+Inputs!$B$52) -> -36.05 | F23: =E23*(1+Inputs!$B$52) -> -37.1315 | G23: =F23*(1+Inputs!$B$52) -> -38.245445 | H23: =G23*(1+Inputs!$B$52) -> -39.392808 | I23: =H23*(1+Inputs!$B$52) -> -40.574593 | J23: =I23*(1+Inputs!$B$52) -> -41.79183 | K23: =J23*(1+Inputs!$B$52) -> -43.045585 | L23: =K23*(1+Inputs!$B$52) -> -44.336953 | M23: =L23*(1+Inputs!$B$52) -> -45.667061
A24: Group adjusted operating profit | C24: =C19+C21+C22+C23 -> 647 | D24: =D19+D21+D22+D23 -> 686 | E24: =E19+E21+E22+E23 -> 808.9 | F24: =F19+F21+F22+F23 -> 900.5875 | G24: =G19+G21+G22+G23 -> 1000.7395 | H24: =H19+H21+H22+H23 -> 1066.5017 | I24: =I19+I21+I22+I23 -> 1127.9233 | J24: =J19+J21+J22+J23 -> 1183.6824 | ... M24: =M19+M21+M22+M23 -> 1304.8479
A25: Adjusted operating margin | C25: =C24/C15 -> 0.18027306 | D25: =D24/D15 -> 0.18033649 | E25: =E24/E15 -> 0.19753358 | F25: =F24/F15 -> 0.20672509 | G25: =G24/G15 -> 0.2158856 | H25: =H24/H15 -> 0.2175166 | I25: =I24/I15 -> 0.21881923 | J25: =J24/J15 -> 0.21979144 | ... M25: =M24/M15 -> 0.22069601
A27: Depreciation and amortisation | C27: 138 | D27: =Inputs!$B$48*D15 -> 144.552 | E27: =Inputs!$B$48*E15 -> 155.61 | F27: =Inputs!$B$48*F15 -> 165.5451 | G27: =Inputs!$B$48*G15 -> 176.14932 | H27: =Inputs!$B$48*H15 -> 186.3171 | I27: =Inputs!$B$48*I15 -> 195.87441 | J27: =Inputs!$B$48*J15 -> 204.64825 | K27: =Inputs!$B$48*K15 -> 212.47222 | ... M27: =Inputs!$B$48*M15 -> 224.67203
A28: Adjusted EBITDA | C28: =C24+C27 -> 785 | D28: =D24+D27 -> 830.552 | E28: =E24+E27 -> 964.51 | F28: =F24+F27 -> 1066.1326 | G28: =G24+G27 -> 1176.8889 | H28: =H24+H27 -> 1252.8188 | I28: =I24+I27 -> 1323.7977 | J28: =J24+J27 -> 1388.3307 | ... M28: =M24+M27 -> 1529.5199
A29: Lease payments | C29: -31 | D29: =-Inputs!$B$50*D15 -> -34.236 | E29: =-Inputs!$B$50*E15 -> -36.855 | F29: =-Inputs!$B$50*F15 -> -39.20805 | G29: =-Inputs!$B$50*G15 -> -41.719577 | H29: =-Inputs!$B$50*H15 -> -44.127735 | I29: =-Inputs!$B$50*I15 -> -46.391308 | J29: =-Inputs!$B$50*J15 -> -48.469321 | K29: =-Inputs!$B$50*K15 -> -50.322367 | ... M29: =-Inputs!$B$50*M15 -> -53.211796
A30: Capital expenditure | C30: -94 | D30: =-Inputs!$B$49*D15 -> -114.12 | E30: =-Inputs!$B$49*E15 -> -122.85 | F30: =-Inputs!$B$49*F15 -> -130.6935 | G30: =-Inputs!$B$49*G15 -> -139.06526 | H30: =-Inputs!$B$49*H15 -> -147.09245 | I30: =-Inputs!$B$49*I15 -> -154.63769 | J30: =-Inputs!$B$49*J15 -> -161.5644 | K30: =-Inputs!$B$49*K15 -> -167.74122 | ... M30: =-Inputs!$B$49*M15 -> -177.37265
A31: Working capital (excluding VC) | B31: 2025: stock and debtors | C31: 33 | D31: =-Inputs!$B$51*(D15-C15) -> -21.5 | E31: =-Inputs!$B$51*(E15-D15) -> -29.1 | F31: =-Inputs!$B$51*(F15-E15) -> -26.145 | G31: =-Inputs!$B$51*(G15-F15) -> -27.90585 | H31: =-Inputs!$B$51*(H15-G15) -> -26.757321 | I31: =-Inputs!$B$51*(I15-H15) -> -25.150803 | J31: =-Inputs!$B$51*(J15-I15) -> -23.089043 | K31: =-Inputs!$B$51*(K15-J15) -> -20.589398 | ... M31: =-Inputs!$B$51*(M15-L15) -> -14.420541
A32: Non-cash VC as % of Engines revenue | B32: Lever for 2029 and 2035 | C32: =-C33/C11 -> 0.19852941 | D32: =Inputs!$B$25/Inputs!$B$20 -> 0.20571429 | E32: =$D32+(Scenarios!$C$8-$D32)*E7 -> 0.17380952 | F32: =$D32+(Scenarios!$C$8-$D32)*F7 -> 0.14190476 | G32: =$D32+(Scenarios!$C$8-$D32)*G7 -> 0.11 | H32: =$G$32+(Scenarios!$C$9-$G$32)*H6/6 -> 0.1 | I32: =$G$32+(Scenarios!$C$9-$G$32)*I6/6 -> 0.09 | J32: =$G$32+(Scenarios!$C$9-$G$32)*J6/6 -> 0.08 | K32: =$G$32+(Scenarios!$C$9-$G$32)*K6/6 -> 0.07 | L32: =$G$32+(Scenarios!$C$9-$G$32)*L6/6 -> 0.06 | M32: =$G$32+(Scenarios!$C$9-$G$32)*M6/6 -> 0.05
A33: Non-cash variable consideration | B33: Profit not yet received | C33: -324 | D33: =-D32*D11 -> -360 | E33: =-E32*E11 -> -328.5 | F33: =-F32*F11 -> -289.656 | G33: =-G32*G11 -> -242.49456 | H33: =-H32*H11 -> -236.06478 | I33: =-I32*I11 -> -225.5599 | J33: =-J32*J11 -> -211.02382 | K33: =-K32*K11 -> -192.64716 | ... M33: =-M32*M11 -> -145.86429
A34: GTF powder-metal payments | C34: -68 | D34: =-Inputs!$B$56 -> -50 | E34: =-Inputs!$B$57 -> -30 | F34: =-Inputs!$B$58 -> -15 | G34: 0 | H34: 0 | I34: 0 | J34: 0 | K34: 0 | L34: 0 | M34: 0
A35: Pension contributions | C35: -22 | D35: =-Inputs!$B$53 -> -5 | E35: =-Inputs!$B$53 -> -5 | F35: =-Inputs!$B$53 -> -5 | G35: =-Inputs!$B$53 -> -5 | H35: =-Inputs!$B$53 -> -5 | I35: =-Inputs!$B$53 -> -5 | J35: =-Inputs!$B$53 -> -5 | K35: =-Inputs!$B$53 -> -5 | ... M35: =-Inputs!$B$53 -> -5
A36: Restructuring and other | B36: 2025: incl. contract releases | C36: -27 | D36: =-Inputs!$B$59 -> -25 | E36: =-Inputs!$B$60 -> -15 | F36: =-Inputs!$B$61 -> -5 | G36: 0 | H36: 0 | I36: 0 | J36: 0 | K36: 0 | L36: 0 | M36: 0
A37: Cash flow before tax | B37: 2025 ties to £252m reported | C37: =C24+C27+C29+C30+C31+C33+C34+C35+C36 -> 252 | D37: =D24+D27+D29+D30+D31+D33+D34+D35+D36 -> 220.696 | E37: =E24+E27+E29+E30+E31+E33+E34+E35+E36 -> 397.205 | F37: =F24+F27+F29+F30+F31+F33+F34+F35+F36 -> 555.43005 | G37: =G24+G27+G29+G30+G31+G33+G34+G35+G36 -> 720.70361 | H37: =H24+H27+H29+H30+H31+H33+H34+H35+H36 -> 793.77647 | I37: =I24+I27+I29+I30+I31+I33+I34+I35+I36 -> 867.05805 | J37: =J24+J27+J29+J30+J31+J33+J34+J35+J36 -> 939.18409 | ... M37: =M24+M27+M29+M30+M31+M33+M34+M35+M36 -> 1133.6507
A38: Tax | B38: Rate x (profit less non-cash VC) | D38: =-Inputs!$B$55*MAX(0,D24+D33) -> -66.504 | E38: =-Inputs!$B$55*MAX(0,E24+E33) -> -98.0016 | F38: =-Inputs!$B$55*MAX(0,F24+F33) -> -124.63003 | G38: =-Inputs!$B$55*MAX(0,G24+G33) -> -154.68197 | H38: =-Inputs!$B$55*MAX(0,H24+H33) -> -169.40912 | I38: =-Inputs!$B$55*MAX(0,I24+I33) -> -184.08214 | J38: =-Inputs!$B$55*MAX(0,J24+J33) -> -198.42236 | K38: =-Inputs!$B$55*MAX(0,K24+K33) -> -212.13204 | ... M38: =-Inputs!$B$55*MAX(0,M24+M33) -> -236.43266
A39: Unlevered free cash flow (FCFF) | D39: =D37+D38 -> 154.192 | E39: =E37+E38 -> 299.2034 | F39: =F37+F38 -> 430.80002 | G39: =G37+G38 -> 566.02164 | H39: =H37+H38 -> 624.36735 | I39: =I37+I38 -> 682.97591 | J39: =J37+J38 -> 740.76174 | K39: =K37+K38 -> 796.55014 | ... M39: =M37+M38 -> 897.218
A40: Less: H1 2026 (already in net debt) | D40: =-Inputs!$B$46 -> -75.236 | E40: 0 | F40: 0 | G40: 0 | H40: 0 | I40: 0 | J40: 0 | K40: 0 | L40: 0 | M40: 0
A41: Cash flow to discount | D41: =D39+D40 -> 78.956 | E41: =E39+E40 -> 299.2034 | F41: =F39+F40 -> 430.80002 | G41: =G39+G40 -> 566.02164 | H41: =H39+H40 -> 624.36735 | I41: =I39+I40 -> 682.97591 | J41: =J39+J40 -> 740.76174 | K41: =K39+K40 -> 796.55014 | ... M41: =M39+M40 -> 897.218
A42: Discount factor | D42: =1/(1+Inputs!$B$71)^D8 -> 0.97788941 | E42: =1/(1+Inputs!$B$71)^E8 -> 0.91444792 | F42: =1/(1+Inputs!$B$71)^F8 -> 0.836215 | G42: =1/(1+Inputs!$B$71)^G8 -> 0.76467507 | H42: =1/(1+Inputs!$B$71)^H8 -> 0.69925552 | I42: =1/(1+Inputs!$B$71)^I8 -> 0.63943276 | J42: =1/(1+Inputs!$B$71)^J8 -> 0.58472796 | K42: =1/(1+Inputs!$B$71)^K8 -> 0.53470326 | ... M42: =1/(1+Inputs!$B$71)^M8 -> 0.44712689
A43: Present value | D43: =D41*D42 -> 77.210236 | E43: =E41*E42 -> 273.60593 | F43: =F41*F42 -> 360.24144 | G43: =G41*G42 -> 432.82263 | H43: =H41*H42 -> 436.59232 | I43: =I41*I42 -> 436.71717 | J43: =J41*J42 -> 433.1441 | K43: =K41*K42 -> 425.91796 | ... M43: =M41*M42 -> 401.17029
A45: Valuation
...

Sheet DCF_Bear
A1: Discounted cash flow: bear case
A2: £m unless stated. Forecasts at US$1.37/£, the 2026 guidance rate. Valued at 30 Jun 2026, the date of the latest net debt.
A4: Year | B4: Note | C4: 2025A | D4: 2026E | E4: 2027E | F4: 2028E | G4: 2029E | H4: 2030E | I4: 2031E | J4: 2032E | K4: 2033E | L4: 2034E | M4: 2035E
A5: Year (number) | C5: 2025 | D5: 2026 | E5: 2027 | F5: 2028 | G5: 2029 | H5: 2030 | I5: 2031 | J5: 2032 | K5: 2033 | L5: 2034 | M5: 2035
A6: Years after 2029 | D6: =MAX(0,D5-2029) -> 0 | E6: =MAX(0,E5-2029) -> 0 | F6: =MAX(0,F5-2029) -> 0 | G6: =MAX(0,G5-2029) -> 0 | H6: =MAX(0,H5-2029) -> 1 | I6: =MAX(0,I5-2029) -> 2 | J6: =MAX(0,J5-2029) -> 3 | K6: =MAX(0,K5-2029) -> 4 | ... M6: =MAX(0,M5-2029) -> 6
A7: Progress to 2029 levels | B7: 0 in 2026, 1 by 2029 | D7: =MIN(MAX(D5-2026,0),3)/3 -> 0 | E7: =MIN(MAX(E5-2026,0),3)/3 -> 0.33333333 | F7: =MIN(MAX(F5-2026,0),3)/3 -> 0.66666667 | G7: =MIN(MAX(G5-2026,0),3)/3 -> 1 | H7: =MIN(MAX(H5-2026,0),3)/3 -> 1 | I7: =MIN(MAX(I5-2026,0),3)/3 -> 1 | J7: =MIN(MAX(J5-2026,0),3)/3 -> 1 | K7: =MIN(MAX(K5-2026,0),3)/3 -> 1 | ... M7: =MIN(MAX(M5-2026,0),3)/3 -> 1
A8: Discount period (years) | B8: From 30 Jun 2026, mid-period | D8: 0.25 | E8: =E5-2026 -> 1 | F8: =F5-2026 -> 2 | G8: =G5-2026 -> 3 | H8: =H5-2026 -> 4 | I8: =I5-2026 -> 5 | J8: =J5-2026 -> 6 | K8: =K5-2026 -> 7 | L8: =L5-2026 -> 8 | M8: =M5-2026 -> 9
A10: Engines revenue growth | B10: 2027-29 lever, then fades | D10: =D11/C11-1 -> 0.072303922 | E10: =Scenarios!$B$4 -> 0.05 | F10: =Scenarios!$B$4 -> 0.05 | G10: =Scenarios!$B$4 -> 0.05 | H10: =Scenarios!$B$4+(Inputs!$B$54-Scenarios!$B$4)*H6/6 -> 0.045833333 | I10: =Scenarios!$B$4+(Inputs!$B$54-Scenarios!$B$4)*I6/6 -> 0.041666667 | J10: =Scenarios!$B$4+(Inputs!$B$54-Scenarios!$B$4)*J6/6 -> 0.0375 | K10: =Scenarios!$B$4+(Inputs!$B$54-Scenarios!$B$4)*K6/6 -> 0.033333333 | L10: =Scenarios!$B$4+(Inputs!$B$54-Scenarios!$B$4)*L6/6 -> 0.029166667 | M10: =Scenarios!$B$4+(Inputs!$B$54-Scenarios!$B$4)*M6/6 -> 0.025
A11: Engines revenue | B11: 2026 = guidance mid-point | C11: 1632 | D11: =Inputs!$B$20 -> 1750 | E11: =D11*(1+E10) -> 1837.5 | F11: =E11*(1+F10) -> 1929.375 | G11: =F11*(1+G10) -> 2025.8438 | H11: =G11*(1+H10) -> 2118.6949 | I11: =H11*(1+I10) -> 2206.9739 | J11: =I11*(1+J10) -> 2289.7354 | K11: =J11*(1+K10) -> 2366.0599 | L11: =K11*(1+L10) -> 2435.07 | M11: =L11*(1+M10) -> 2495.9467
A12: Airframes revenue growth | B12: 2027-29 lever, then fades | D12: =D13/C13-1 -> 0.073071027 | E12: =Scenarios!$B$6 -> 0.03 | F12: =Scenarios!$B$6 -> 0.03 | G12: =Scenarios!$B$6 -> 0.03 | H12: =Scenarios!$B$6+(Inputs!$B$54-Scenarios!$B$6)*H6/6 -> 0.029166667 | I12: =Scenarios!$B$6+(Inputs!$B$54-Scenarios!$B$6)*I6/6 -> 0.028333333 | J12: =Scenarios!$B$6+(Inputs!$B$54-Scenarios!$B$6)*J6/6 -> 0.0275 | K12: =Scenarios!$B$6+(Inputs!$B$54-Scenarios!$B$6)*K6/6 -> 0.026666667 | L12: =Scenarios!$B$6+(Inputs!$B$54-Scenarios!$B$6)*L6/6 -> 0.025833333 | M12: =Scenarios!$B$6+(Inputs!$B$54-Scenarios!$B$6)*M6/6 -> 0.025
A13: Airframes revenue (before Garden Grove) | B13: 2026 = guidance | C13: 1957 | D13: =Inputs!$B$22 -> 2100 | E13: =D13*(1+E12) -> 2163 | F13: =E13*(1+F12) -> 2227.89 | G13: =F13*(1+G12) -> 2294.7267 | H13: =G13*(1+H12) -> 2361.6562 | I13: =H13*(1+I12) -> 2428.5698 | J13: =I13*(1+J12) -> 2495.3555 | K13: =J13*(1+K12) -> 2561.8983 | L13: =K13*(1+L12) -> 2628.0807 | M13: =L13*(1+M12) -> 2693.7827
A14: Garden Grove lost revenue | B14: 2026 only | C14: 0 | D14: =-Inputs!$B$38 -> -46 | E14: 0 | F14: 0 | G14: 0 | H14: 0 | I14: 0 | J14: 0 | K14: 0 | L14: 0 | M14: 0
A15: Group revenue | C15: =C11+C13+C14 -> 3589 | D15: =D11+D13+D14 -> 3804 | E15: =E11+E13+E14 -> 4000.5 | F15: =F11+F13+F14 -> 4157.265 | G15: =G11+G13+G14 -> 4320.5705 | H15: =H11+H13+H14 -> 4480.3512 | I15: =I11+I13+I14 -> 4635.5437 | J15: =J11+J13+J14 -> 4785.0909 | ... M15: =M11+M13+M14 -> 5189.7294
A16: Revenue growth | D16: =D15/C15-1 -> 0.059905266 | E16: =E15/D15-1 -> 0.051656151 | F16: =F15/E15-1 -> 0.039186352 | G16: =G15/F15-1 -> 0.039281944 | H16: =H15/G15-1 -> 0.03698139 | I16: =I15/H15-1 -> 0.034638479 | J16: =J15/I15-1 -> 0.032260982 | K16: =K15/J15-1 -> 0.029856763 | ... M16: =M15/L15-1 -> 0.025
A18: Engines margin | B18: Straight line to the 2029 lever | C18: =C19/C11 -> 0.31862745 | D18: =Inputs!$B$21/Inputs!$B$20 -> 0.33142857 | E18: =$D18+(Scenarios!$B$5-$D18)*E7 -> 0.32761905 | F18: =$D18+(Scenarios!$B$5-$D18)*F7 -> 0.32380952 | G18: =$D18+(Scenarios!$B$5-$D18)*G7 -> 0.32 | H18: =$D18+(Scenarios!$B$5-$D18)*H7 -> 0.32 | I18: =$D18+(Scenarios!$B$5-$D18)*I7 -> 0.32 | J18: =$D18+(Scenarios!$B$5-$D18)*J7 -> 0.32 | K18: =$D18+(Scenarios!$B$5-$D18)*K7 -> 0.32 | L18: =$D18+(Scenarios!$B$5-$D18)*L7 -> 0.32 | M18: =$D18+(Scenarios!$B$5-$D18)*M7 -> 0.32
A19: Engines adjusted operating profit | C19: 520 | D19: =D11*D18 -> 580 | E19: =E11*E18 -> 602 | F19: =F11*F18 -> 624.75 | G19: =G11*G18 -> 648.27 | H19: =H11*H18 -> 677.98238 | I19: =I11*I18 -> 706.23164 | J19: =J11*J18 -> 732.71533 | K19: =K11*K18 -> 757.13917 | ... M19: =M11*M18 -> 798.70296
A20: Airframes margin | B20: Straight line to the 2029 lever | C20: =C21/C13 -> 0.079713848 | D20: =Inputs!$B$23/Inputs!$B$22 -> 0.085714286 | E20: =$D20+(Scenarios!$B$7-$D20)*E7 -> 0.08547619 | F20: =$D20+(Scenarios!$B$7-$D20)*F7 -> 0.085238095 | G20: =$D20+(Scenarios!$B$7-$D20)*G7 -> 0.085 | H20: =$D20+(Scenarios!$B$7-$D20)*H7 -> 0.085 | I20: =$D20+(Scenarios!$B$7-$D20)*I7 -> 0.085 | J20: =$D20+(Scenarios!$B$7-$D20)*J7 -> 0.085 | K20: =$D20+(Scenarios!$B$7-$D20)*K7 -> 0.085 | L20: =$D20+(Scenarios!$B$7-$D20)*L7 -> 0.085 | M20: =$D20+(Scenarios!$B$7-$D20)*M7 -> 0.085
A21: Airframes adjusted operating profit | C21: 156 | D21: =D13*D20 -> 180 | E21: =E13*E20 -> 184.885 | F21: =F13*F20 -> 189.9011 | G21: =G13*G20 -> 195.05177 | H21: =H13*H20 -> 200.74078 | I21: =I13*I20 -> 206.42843 | J21: =J13*J20 -> 212.10522 | K21: =K13*K20 -> 217.76136 | ... M21: =M13*M20 -> 228.97153
A22: Garden Grove lost profit | B22: 2026 only | C22: 0 | D22: =-Inputs!$B$39 -> -39 | E22: 0 | F22: 0 | G22: 0 | H22: 0 | I22: 0 | J22: 0 | K22: 0 | L22: 0 | M22: 0
A23: Central costs | B23: Grow with inflation | C23: -29 | D23: =-Inputs!$B$27 -> -35 | E23: =D23*(1+Inputs!$B$52) -> -36.05 | F23: =E23*(1+Inputs!$B$52) -> -37.1315 | G23: =F23*(1+Inputs!$B$52) -> -38.245445 | H23: =G23*(1+Inputs!$B$52) -> -39.392808 | I23: =H23*(1+Inputs!$B$52) -> -40.574593 | J23: =I23*(1+Inputs!$B$52) -> -41.79183 | K23: =J23*(1+Inputs!$B$52) -> -43.045585 | L23: =K23*(1+Inputs!$B$52) -> -44.336953 | M23: =L23*(1+Inputs!$B$52) -> -45.667061
A24: Group adjusted operating profit | C24: =C19+C21+C22+C23 -> 647 | D24: =D19+D21+D22+D23 -> 686 | E24: =E19+E21+E22+E23 -> 750.835 | F24: =F19+F21+F22+F23 -> 777.5196 | G24: =G19+G21+G22+G23 -> 805.07632 | H24: =H19+H21+H22+H23 -> 839.33035 | I24: =I19+I21+I22+I23 -> 872.08548 | J24: =J19+J21+J22+J23 -> 903.02871 | ... M24: =M19+M21+M22+M23 -> 982.00742
A25: Adjusted operating margin | C25: =C24/C15 -> 0.18027306 | D25: =D24/D15 -> 0.18033649 | E25: =E24/E15 -> 0.18768529 | F25: =F24/F15 -> 0.18702671 | G25: =G24/G15 -> 0.18633565 | H25: =H24/H15 -> 0.18733584 | I25: =I24/I15 -> 0.18813014 | J25: =J24/J15 -> 0.18871715 | ... M25: =M24/M15 -> 0.18922131
A27: Depreciation and amortisation | C27: 138 | D27: =Inputs!$B$48*D15 -> 144.552 | E27: =Inputs!$B$48*E15 -> 152.019 | F27: =Inputs!$B$48*F15 -> 157.97607 | G27: =Inputs!$B$48*G15 -> 164.18168 | H27: =Inputs!$B$48*H15 -> 170.25334 | I27: =Inputs!$B$48*I15 -> 176.15066 | J27: =Inputs!$B$48*J15 -> 181.83345 | K27: =Inputs!$B$48*K15 -> 187.26241 | ... M27: =Inputs!$B$48*M15 -> 197.20972
A28: Adjusted EBITDA | C28: =C24+C27 -> 785 | D28: =D24+D27 -> 830.552 | E28: =E24+E27 -> 902.854 | F28: =F24+F27 -> 935.49567 | G28: =G24+G27 -> 969.258 | H28: =H24+H27 -> 1009.5837 | I28: =I24+I27 -> 1048.2361 | J28: =J24+J27 -> 1084.8622 | ... M28: =M24+M27 -> 1179.2171
A29: Lease payments | C29: -31 | D29: =-Inputs!$B$50*D15 -> -34.236 | E29: =-Inputs!$B$50*E15 -> -36.0045 | F29: =-Inputs!$B$50*F15 -> -37.415385 | G29: =-Inputs!$B$50*G15 -> -38.885134 | H29: =-Inputs!$B$50*H15 -> -40.32316 | I29: =-Inputs!$B$50*I15 -> -41.719893 | J29: =-Inputs!$B$50*J15 -> -43.065818 | K29: =-Inputs!$B$50*K15 -> -44.351624 | ... M29: =-Inputs!$B$50*M15 -> -46.707565
A30: Capital expenditure | C30: -94 | D30: =-Inputs!$B$49*D15 -> -114.12 | E30: =-Inputs!$B$49*E15 -> -120.015 | F30: =-Inputs!$B$49*F15 -> -124.71795 | G30: =-Inputs!$B$49*G15 -> -129.61711 | H30: =-Inputs!$B$49*H15 -> -134.41053 | I30: =-Inputs!$B$49*I15 -> -139.06631 | J30: =-Inputs!$B$49*J15 -> -143.55273 | K30: =-Inputs!$B$49*K15 -> -147.83875 | ... M30: =-Inputs!$B$49*M15 -> -155.69188
A31: Working capital (excluding VC) | B31: 2025: stock and debtors | C31: 33 | D31: =-Inputs!$B$51*(D15-C15) -> -21.5 | E31: =-Inputs!$B$51*(E15-D15) -> -19.65 | F31: =-Inputs!$B$51*(F15-E15) -> -15.6765 | G31: =-Inputs!$B$51*(G15-F15) -> -16.330545 | H31: =-Inputs!$B$51*(H15-G15) -> -15.97807 | I31: =-Inputs!$B$51*(I15-H15) -> -15.519255 | J31: =-Inputs!$B$51*(J15-I15) -> -14.954719 | K31: =-Inputs!$B$51*(K15-J15) -> -14.286733 | ... M31: =-Inputs!$B$51*(M15-L15) -> -12.657877
A32: Non-cash VC as % of Engines revenue | B32: Lever for 2029 and 2035 | C32: =-C33/C11 -> 0.19852941 | D32: =Inputs!$B$25/Inputs!$B$20 -> 0.20571429 | E32: =$D32+(Scenarios!$B$8-$D32)*E7 -> 0.19047619 | F32: =$D32+(Scenarios!$B$8-$D32)*F7 -> 0.1752381 | G32: =$D32+(Scenarios!$B$8-$D32)*G7 -> 0.16 | H32: =$G$32+(Scenarios!$B$9-$G$32)*H6/6 -> 0.14666667 | I32: =$G$32+(Scenarios!$B$9-$G$32)*I6/6 -> 0.13333333 | J32: =$G$32+(Scenarios!$B$9-$G$32)*J6/6 -> 0.12 | K32: =$G$32+(Scenarios!$B$9-$G$32)*K6/6 -> 0.10666667 | L32: =$G$32+(Scenarios!$B$9-$G$32)*L6/6 -> 0.093333333 | M32: =$G$32+(Scenarios!$B$9-$G$32)*M6/6 -> 0.08
A33: Non-cash variable consideration | B33: Profit not yet received | C33: -324 | D33: =-D32*D11 -> -360 | E33: =-E32*E11 -> -350 | F33: =-F32*F11 -> -338.1 | G33: =-G32*G11 -> -324.135 | H33: =-H32*H11 -> -310.74192 | I33: =-I32*I11 -> -294.26318 | J33: =-J32*J11 -> -274.76825 | K33: =-K32*K11 -> -252.37972 | ... M33: =-M32*M11 -> -199.67574
A34: GTF powder-metal payments | C34: -68 | D34: =-Inputs!$B$56 -> -50 | E34: =-Inputs!$B$57 -> -30 | F34: =-Inputs!$B$58 -> -15 | G34: 0 | H34: 0 | I34: 0 | J34: 0 | K34: 0 | L34: 0 | M34: 0
A35: Pension contributions | C35: -22 | D35: =-Inputs!$B$53 -> -5 | E35: =-Inputs!$B$53 -> -5 | F35: =-Inputs!$B$53 -> -5 | G35: =-Inputs!$B$53 -> -5 | H35: =-Inputs!$B$53 -> -5 | I35: =-Inputs!$B$53 -> -5 | J35: =-Inputs!$B$53 -> -5 | K35: =-Inputs!$B$53 -> -5 | ... M35: =-Inputs!$B$53 -> -5
A36: Restructuring and other | B36: 2025: incl. contract releases | C36: -27 | D36: =-Inputs!$B$59 -> -25 | E36: =-Inputs!$B$60 -> -15 | F36: =-Inputs!$B$61 -> -5 | G36: 0 | H36: 0 | I36: 0 | J36: 0 | K36: 0 | L36: 0 | M36: 0
A37: Cash flow before tax | B37: 2025 ties to £252m reported | C37: =C24+C27+C29+C30+C31+C33+C34+C35+C36 -> 252 | D37: =D24+D27+D29+D30+D31+D33+D34+D35+D36 -> 220.696 | E37: =E24+E27+E29+E30+E31+E33+E34+E35+E36 -> 327.1845 | F37: =F24+F27+F29+F30+F31+F33+F34+F35+F36 -> 394.58583 | G37: =G24+G27+G29+G30+G31+G33+G34+G35+G36 -> 455.29021 | H37: =H24+H27+H29+H30+H31+H33+H34+H35+H36 -> 503.13 | I37: =I24+I27+I29+I30+I31+I33+I34+I35+I36 -> 552.6675 | J37: =J24+J27+J29+J30+J31+J33+J34+J35+J36 -> 603.52066 | ... M37: =M24+M27+M29+M30+M31+M33+M34+M35+M36 -> 759.48408
A38: Tax | B38: Rate x (profit less non-cash VC) | D38: =-Inputs!$B$55*MAX(0,D24+D33) -> -66.504 | E38: =-Inputs!$B$55*MAX(0,E24+E33) -> -81.77034 | F38: =-Inputs!$B$55*MAX(0,F24+F33) -> -89.641598 | G38: =-Inputs!$B$55*MAX(0,G24+G33) -> -98.11203 | H38: =-Inputs!$B$55*MAX(0,H24+H33) -> -107.83204 | I38: =-Inputs!$B$55*MAX(0,I24+I33) -> -117.87575 | J38: =-Inputs!$B$55*MAX(0,J24+J33) -> -128.16514 | K38: =-Inputs!$B$55*MAX(0,K24+K33) -> -138.61294 | ... M38: =-Inputs!$B$55*MAX(0,M24+M33) -> -159.59566
A39: Unlevered free cash flow (FCFF) | D39: =D37+D38 -> 154.192 | E39: =E37+E38 -> 245.41416 | F39: =F37+F38 -> 304.94424 | G39: =G37+G38 -> 357.17818 | H39: =H37+H38 -> 395.29796 | I39: =I37+I38 -> 434.79175 | J39: =J37+J38 -> 475.35552 | K39: =K37+K38 -> 516.64758 | ... M39: =M37+M38 -> 599.88842
A40: Less: H1 2026 (already in net debt) | D40: =-Inputs!$B$46 -> -75.236 | E40: 0 | F40: 0 | G40: 0 | H40: 0 | I40: 0 | J40: 0 | K40: 0 | L40: 0 | M40: 0
A41: Cash flow to discount | D41: =D39+D40 -> 78.956 | E41: =E39+E40 -> 245.41416 | F41: =F39+F40 -> 304.94424 | G41: =G39+G40 -> 357.17818 | H41: =H39+H40 -> 395.29796 | I41: =I39+I40 -> 434.79175 | J41: =J39+J40 -> 475.35552 | K41: =K39+K40 -> 516.64758 | ... M41: =M39+M40 -> 599.88842
A42: Discount factor | D42: =1/(1+Inputs!$B$71)^D8 -> 0.97788941 | E42: =1/(1+Inputs!$B$71)^E8 -> 0.91444792 | F42: =1/(1+Inputs!$B$71)^F8 -> 0.836215 | G42: =1/(1+Inputs!$B$71)^G8 -> 0.76467507 | H42: =1/(1+Inputs!$B$71)^H8 -> 0.69925552 | I42: =1/(1+Inputs!$B$71)^I8 -> 0.63943276 | J42: =1/(1+Inputs!$B$71)^J8 -> 0.58472796 | K42: =1/(1+Inputs!$B$71)^K8 -> 0.53470326 | ... M42: =1/(1+Inputs!$B$71)^M8 -> 0.44712689
A43: Present value | D43: =D41*D42 -> 77.210236 | E43: =E41*E42 -> 224.41847 | F43: =F41*F42 -> 254.99894 | G43: =G41*G42 -> 273.12525 | H43: =H41*H42 -> 276.41428 | I43: =I41*I42 -> 278.02009 | J43: =J41*J42 -> 277.95366 | K43: =K41*K42 -> 276.25315 | ... M43: =M41*M42 -> 268.22624
A45: Valuation
...

Sheet DCF_Bull
A1: Discounted cash flow: bull case
A2: £m unless stated. Forecasts at US$1.37/£, the 2026 guidance rate. Valued at 30 Jun 2026, the date of the latest net debt.
A4: Year | B4: Note | C4: 2025A | D4: 2026E | E4: 2027E | F4: 2028E | G4: 2029E | H4: 2030E | I4: 2031E | J4: 2032E | K4: 2033E | L4: 2034E | M4: 2035E
A5: Year (number) | C5: 2025 | D5: 2026 | E5: 2027 | F5: 2028 | G5: 2029 | H5: 2030 | I5: 2031 | J5: 2032 | K5: 2033 | L5: 2034 | M5: 2035
A6: Years after 2029 | D6: =MAX(0,D5-2029) -> 0 | E6: =MAX(0,E5-2029) -> 0 | F6: =MAX(0,F5-2029) -> 0 | G6: =MAX(0,G5-2029) -> 0 | H6: =MAX(0,H5-2029) -> 1 | I6: =MAX(0,I5-2029) -> 2 | J6: =MAX(0,J5-2029) -> 3 | K6: =MAX(0,K5-2029) -> 4 | ... M6: =MAX(0,M5-2029) -> 6
A7: Progress to 2029 levels | B7: 0 in 2026, 1 by 2029 | D7: =MIN(MAX(D5-2026,0),3)/3 -> 0 | E7: =MIN(MAX(E5-2026,0),3)/3 -> 0.33333333 | F7: =MIN(MAX(F5-2026,0),3)/3 -> 0.66666667 | G7: =MIN(MAX(G5-2026,0),3)/3 -> 1 | H7: =MIN(MAX(H5-2026,0),3)/3 -> 1 | I7: =MIN(MAX(I5-2026,0),3)/3 -> 1 | J7: =MIN(MAX(J5-2026,0),3)/3 -> 1 | K7: =MIN(MAX(K5-2026,0),3)/3 -> 1 | ... M7: =MIN(MAX(M5-2026,0),3)/3 -> 1
A8: Discount period (years) | B8: From 30 Jun 2026, mid-period | D8: 0.25 | E8: =E5-2026 -> 1 | F8: =F5-2026 -> 2 | G8: =G5-2026 -> 3 | H8: =H5-2026 -> 4 | I8: =I5-2026 -> 5 | J8: =J5-2026 -> 6 | K8: =K5-2026 -> 7 | L8: =L5-2026 -> 8 | M8: =M5-2026 -> 9
A10: Engines revenue growth | B10: 2027-29 lever, then fades | D10: =D11/C11-1 -> 0.072303922 | E10: =Scenarios!$D$4 -> 0.1 | F10: =Scenarios!$D$4 -> 0.1 | G10: =Scenarios!$D$4 -> 0.1 | H10: =Scenarios!$D$4+(Inputs!$B$54-Scenarios!$D$4)*H6/6 -> 0.0875 | I10: =Scenarios!$D$4+(Inputs!$B$54-Scenarios!$D$4)*I6/6 -> 0.075 | J10: =Scenarios!$D$4+(Inputs!$B$54-Scenarios!$D$4)*J6/6 -> 0.0625 | K10: =Scenarios!$D$4+(Inputs!$B$54-Scenarios!$D$4)*K6/6 -> 0.05 | L10: =Scenarios!$D$4+(Inputs!$B$54-Scenarios!$D$4)*L6/6 -> 0.0375 | M10: =Scenarios!$D$4+(Inputs!$B$54-Scenarios!$D$4)*M6/6 -> 0.025
A11: Engines revenue | B11: 2026 = guidance mid-point | C11: 1632 | D11: =Inputs!$B$20 -> 1750 | E11: =D11*(1+E10) -> 1925 | F11: =E11*(1+F10) -> 2117.5 | G11: =F11*(1+G10) -> 2329.25 | H11: =G11*(1+H10) -> 2533.0594 | I11: =H11*(1+I10) -> 2723.0388 | J11: =I11*(1+J10) -> 2893.2288 | K11: =J11*(1+K10) -> 3037.8902 | L11: =K11*(1+L10) -> 3151.8111 | M11: =L11*(1+M10) -> 3230.6064
A12: Airframes revenue growth | B12: 2027-29 lever, then fades | D12: =D13/C13-1 -> 0.073071027 | E12: =Scenarios!$D$6 -> 0.065 | F12: =Scenarios!$D$6 -> 0.065 | G12: =Scenarios!$D$6 -> 0.065 | H12: =Scenarios!$D$6+(Inputs!$B$54-Scenarios!$D$6)*H6/6 -> 0.058333333 | I12: =Scenarios!$D$6+(Inputs!$B$54-Scenarios!$D$6)*I6/6 -> 0.051666667 | J12: =Scenarios!$D$6+(Inputs!$B$54-Scenarios!$D$6)*J6/6 -> 0.045 | K12: =Scenarios!$D$6+(Inputs!$B$54-Scenarios!$D$6)*K6/6 -> 0.038333333 | L12: =Scenarios!$D$6+(Inputs!$B$54-Scenarios!$D$6)*L6/6 -> 0.031666667 | M12: =Scenarios!$D$6+(Inputs!$B$54-Scenarios!$D$6)*M6/6 -> 0.025
A13: Airframes revenue (before Garden Grove) | B13: 2026 = guidance | C13: 1957 | D13: =Inputs!$B$22 -> 2100 | E13: =D13*(1+E12) -> 2236.5 | F13: =E13*(1+F12) -> 2381.8725 | G13: =F13*(1+G12) -> 2536.6942 | H13: =G13*(1+H12) -> 2684.668 | I13: =H13*(1+I12) -> 2823.3759 | J13: =I13*(1+J12) -> 2950.4278 | K13: =J13*(1+K12) -> 3063.5275 | L13: =K13*(1+L12) -> 3160.5392 | M13: =L13*(1+M12) -> 3239.5527
A14: Garden Grove lost revenue | B14: 2026 only | C14: 0 | D14: =-Inputs!$B$38 -> -46 | E14: 0 | F14: 0 | G14: 0 | H14: 0 | I14: 0 | J14: 0 | K14: 0 | L14: 0 | M14: 0
A15: Group revenue | C15: =C11+C13+C14 -> 3589 | D15: =D11+D13+D14 -> 3804 | E15: =E11+E13+E14 -> 4161.5 | F15: =F11+F13+F14 -> 4499.3725 | G15: =G11+G13+G14 -> 4865.9442 | H15: =H11+H13+H14 -> 5217.7274 | I15: =I11+I13+I14 -> 5546.4147 | J15: =J11+J13+J14 -> 5843.6566 | ... M15: =M11+M13+M14 -> 6470.1591
A16: Revenue growth | D16: =D15/C15-1 -> 0.059905266 | E16: =E15/D15-1 -> 0.093980021 | F16: =F15/E15-1 -> 0.081190076 | G16: =G15/F15-1 -> 0.081471741 | H16: =H15/G15-1 -> 0.072294952 | I16: =I15/H15-1 -> 0.062994341 | J16: =J15/I15-1 -> 0.053591709 | K16: =K15/J15-1 -> 0.044109569 | ... M16: =M15/L15-1 -> 0.025
A18: Engines margin | B18: Straight line to the 2029 lever | C18: =C19/C11 -> 0.31862745 | D18: =Inputs!$B$21/Inputs!$B$20 -> 0.33142857 | E18: =$D18+(Scenarios!$D$5-$D18)*E7 -> 0.34428571 | F18: =$D18+(Scenarios!$D$5-$D18)*F7 -> 0.35714286 | G18: =$D18+(Scenarios!$D$5-$D18)*G7 -> 0.37 | H18: =$D18+(Scenarios!$D$5-$D18)*H7 -> 0.37 | I18: =$D18+(Scenarios!$D$5-$D18)*I7 -> 0.37 | J18: =$D18+(Scenarios!$D$5-$D18)*J7 -> 0.37 | K18: =$D18+(Scenarios!$D$5-$D18)*K7 -> 0.37 | L18: =$D18+(Scenarios!$D$5-$D18)*L7 -> 0.37 | M18: =$D18+(Scenarios!$D$5-$D18)*M7 -> 0.37
A19: Engines adjusted operating profit | C19: 520 | D19: =D11*D18 -> 580 | E19: =E11*E18 -> 662.75 | F19: =F11*F18 -> 756.25 | G19: =G11*G18 -> 861.8225 | H19: =H11*H18 -> 937.23197 | I19: =I11*I18 -> 1007.5244 | J19: =J11*J18 -> 1070.4946 | K19: =K11*K18 -> 1124.0194 | ... M19: =M11*M18 -> 1195.3244
A20: Airframes margin | B20: Straight line to the 2029 lever | C20: =C21/C13 -> 0.079713848 | D20: =Inputs!$B$23/Inputs!$B$22 -> 0.085714286 | E20: =$D20+(Scenarios!$D$7-$D20)*E7 -> 0.098809524 | F20: =$D20+(Scenarios!$D$7-$D20)*F7 -> 0.11190476 | G20: =$D20+(Scenarios!$D$7-$D20)*G7 -> 0.125 | H20: =$D20+(Scenarios!$D$7-$D20)*H7 -> 0.125 | I20: =$D20+(Scenarios!$D$7-$D20)*I7 -> 0.125 | J20: =$D20+(Scenarios!$D$7-$D20)*J7 -> 0.125 | K20: =$D20+(Scenarios!$D$7-$D20)*K7 -> 0.125 | L20: =$D20+(Scenarios!$D$7-$D20)*L7 -> 0.125 | M20: =$D20+(Scenarios!$D$7-$D20)*M7 -> 0.125
A21: Airframes adjusted operating profit | C21: 156 | D21: =D13*D20 -> 180 | E21: =E13*E20 -> 220.9875 | F21: =F13*F20 -> 266.54287 | G21: =G13*G20 -> 317.08678 | H21: =H13*H20 -> 335.58351 | I21: =I13*I20 -> 352.92199 | J21: =J13*J20 -> 368.80348 | K21: =K13*K20 -> 382.94094 | ... M21: =M13*M20 -> 404.94409
A22: Garden Grove lost profit | B22: 2026 only | C22: 0 | D22: =-Inputs!$B$39 -> -39 | E22: 0 | F22: 0 | G22: 0 | H22: 0 | I22: 0 | J22: 0 | K22: 0 | L22: 0 | M22: 0
A23: Central costs | B23: Grow with inflation | C23: -29 | D23: =-Inputs!$B$27 -> -35 | E23: =D23*(1+Inputs!$B$52) -> -36.05 | F23: =E23*(1+Inputs!$B$52) -> -37.1315 | G23: =F23*(1+Inputs!$B$52) -> -38.245445 | H23: =G23*(1+Inputs!$B$52) -> -39.392808 | I23: =H23*(1+Inputs!$B$52) -> -40.574593 | J23: =I23*(1+Inputs!$B$52) -> -41.79183 | K23: =J23*(1+Inputs!$B$52) -> -43.045585 | L23: =K23*(1+Inputs!$B$52) -> -44.336953 | M23: =L23*(1+Inputs!$B$52) -> -45.667061
A24: Group adjusted operating profit | C24: =C19+C21+C22+C23 -> 647 | D24: =D19+D21+D22+D23 -> 686 | E24: =E19+E21+E22+E23 -> 847.6875 | F24: =F19+F21+F22+F23 -> 985.66138 | G24: =G19+G21+G22+G23 -> 1140.6638 | H24: =H19+H21+H22+H23 -> 1233.4227 | I24: =I19+I21+I22+I23 -> 1319.8718 | J24: =J19+J21+J22+J23 -> 1397.5063 | ... M24: =M19+M21+M22+M23 -> 1554.6014
A25: Adjusted operating margin | C25: =C24/C15 -> 0.18027306 | D25: =D24/D15 -> 0.18033649 | E25: =E24/E15 -> 0.20369759 | F25: =F24/F15 -> 0.21906641 | G25: =G24/G15 -> 0.23441778 | H25: =H24/H15 -> 0.23639078 | I25: =I24/I15 -> 0.23796846 | J25: =J24/J15 -> 0.23914928 | ... M25: =M24/M15 -> 0.24027251
A27: Depreciation and amortisation | C27: 138 | D27: =Inputs!$B$48*D15 -> 144.552 | E27: =Inputs!$B$48*E15 -> 158.137 | F27: =Inputs!$B$48*F15 -> 170.97616 | G27: =Inputs!$B$48*G15 -> 184.90588 | H27: =Inputs!$B$48*H15 -> 198.27364 | I27: =Inputs!$B$48*I15 -> 210.76376 | J27: =Inputs!$B$48*J15 -> 222.05895 | K27: =Inputs!$B$48*K15 -> 231.85387 | ... M27: =Inputs!$B$48*M15 -> 245.86604
A28: Adjusted EBITDA | C28: =C24+C27 -> 785 | D28: =D24+D27 -> 830.552 | E28: =E24+E27 -> 1005.8245 | F28: =F24+F27 -> 1156.6375 | G28: =G24+G27 -> 1325.5697 | H28: =H24+H27 -> 1431.6963 | I28: =I24+I27 -> 1530.6355 | J28: =J24+J27 -> 1619.5652 | ... M28: =M24+M27 -> 1800.4674
A29: Lease payments | C29: -31 | D29: =-Inputs!$B$50*D15 -> -34.236 | E29: =-Inputs!$B$50*E15 -> -37.4535 | F29: =-Inputs!$B$50*F15 -> -40.494352 | G29: =-Inputs!$B$50*G15 -> -43.793498 | H29: =-Inputs!$B$50*H15 -> -46.959547 | I29: =-Inputs!$B$50*I15 -> -49.917732 | J29: =-Inputs!$B$50*J15 -> -52.592909 | K29: =-Inputs!$B$50*K15 -> -54.91276 | ... M29: =-Inputs!$B$50*M15 -> -58.231432
A30: Capital expenditure | C30: -94 | D30: =-Inputs!$B$49*D15 -> -114.12 | E30: =-Inputs!$B$49*E15 -> -124.845 | F30: =-Inputs!$B$49*F15 -> -134.98118 | G30: =-Inputs!$B$49*G15 -> -145.97833 | H30: =-Inputs!$B$49*H15 -> -156.53182 | I30: =-Inputs!$B$49*I15 -> -166.39244 | J30: =-Inputs!$B$49*J15 -> -175.3097 | K30: =-Inputs!$B$49*K15 -> -183.04253 | ... M30: =-Inputs!$B$49*M15 -> -194.10477
A31: Working capital (excluding VC) | B31: 2025: stock and debtors | C31: 33 | D31: =-Inputs!$B$51*(D15-C15) -> -21.5 | E31: =-Inputs!$B$51*(E15-D15) -> -35.75 | F31: =-Inputs!$B$51*(F15-E15) -> -33.78725 | G31: =-Inputs!$B$51*(G15-F15) -> -36.657171 | H31: =-Inputs!$B$51*(H15-G15) -> -35.17832 | I31: =-Inputs!$B$51*(I15-H15) -> -32.86873 | J31: =-Inputs!$B$51*(J15-I15) -> -29.724184 | K31: =-Inputs!$B$51*(K15-J15) -> -25.776117 | ... M31: =-Inputs!$B$51*(M15-L15) -> -15.780876
A32: Non-cash VC as % of Engines revenue | B32: Lever for 2029 and 2035 | C32: =-C33/C11 -> 0.19852941 | D32: =Inputs!$B$25/Inputs!$B$20 -> 0.20571429 | E32: =$D32+(Scenarios!$D$8-$D32)*E7 -> 0.16714286 | F32: =$D32+(Scenarios!$D$8-$D32)*F7 -> 0.12857143 | G32: =$D32+(Scenarios!$D$8-$D32)*G7 -> 0.09 | H32: =$G$32+(Scenarios!$D$9-$G$32)*H6/6 -> 0.079166667 | I32: =$G$32+(Scenarios!$D$9-$G$32)*I6/6 -> 0.068333333 | J32: =$G$32+(Scenarios!$D$9-$G$32)*J6/6 -> 0.0575 | K32: =$G$32+(Scenarios!$D$9-$G$32)*K6/6 -> 0.046666667 | L32: =$G$32+(Scenarios!$D$9-$G$32)*L6/6 -> 0.035833333 | M32: =$G$32+(Scenarios!$D$9-$G$32)*M6/6 -> 0.025
A33: Non-cash variable consideration | B33: Profit not yet received | C33: -324 | D33: =-D32*D11 -> -360 | E33: =-E32*E11 -> -321.75 | F33: =-F32*F11 -> -272.25 | G33: =-G32*G11 -> -209.6325 | H33: =-H32*H11 -> -200.53387 | I33: =-I32*I11 -> -186.07432 | J33: =-J32*J11 -> -166.36065 | K33: =-K32*K11 -> -141.76821 | ... M33: =-M32*M11 -> -80.765159
A34: GTF powder-metal payments | C34: -68 | D34: =-Inputs!$B$56 -> -50 | E34: =-Inputs!$B$57 -> -30 | F34: =-Inputs!$B$58 -> -15 | G34: 0 | H34: 0 | I34: 0 | J34: 0 | K34: 0 | L34: 0 | M34: 0
A35: Pension contributions | C35: -22 | D35: =-Inputs!$B$53 -> -5 | E35: =-Inputs!$B$53 -> -5 | F35: =-Inputs!$B$53 -> -5 | G35: =-Inputs!$B$53 -> -5 | H35: =-Inputs!$B$53 -> -5 | I35: =-Inputs!$B$53 -> -5 | J35: =-Inputs!$B$53 -> -5 | K35: =-Inputs!$B$53 -> -5 | ... M35: =-Inputs!$B$53 -> -5
A36: Restructuring and other | B36: 2025: incl. contract releases | C36: -27 | D36: =-Inputs!$B$59 -> -25 | E36: =-Inputs!$B$60 -> -15 | F36: =-Inputs!$B$61 -> -5 | G36: 0 | H36: 0 | I36: 0 | J36: 0 | K36: 0 | L36: 0 | M36: 0
A37: Cash flow before tax | B37: 2025 ties to £252m reported | C37: =C24+C27+C29+C30+C31+C33+C34+C35+C36 -> 252 | D37: =D24+D27+D29+D30+D31+D33+D34+D35+D36 -> 220.696 | E37: =E24+E27+E29+E30+E31+E33+E34+E35+E36 -> 436.026 | F37: =F24+F27+F29+F30+F31+F33+F34+F35+F36 -> 650.12475 | G37: =G24+G27+G29+G30+G31+G33+G34+G35+G36 -> 884.50822 | H37: =H24+H27+H29+H30+H31+H33+H34+H35+H36 -> 987.49275 | I37: =I24+I27+I29+I30+I31+I33+I34+I35+I36 -> 1090.3823 | J37: =J24+J27+J29+J30+J31+J33+J34+J35+J36 -> 1190.5778 | ... M37: =M24+M27+M29+M30+M31+M33+M34+M35+M36 -> 1446.5852
A38: Tax | B38: Rate x (profit less non-cash VC) | D38: =-Inputs!$B$55*MAX(0,D24+D33) -> -66.504 | E38: =-Inputs!$B$55*MAX(0,E24+E33) -> -107.29125 | F38: =-Inputs!$B$55*MAX(0,F24+F33) -> -145.53592 | G38: =-Inputs!$B$55*MAX(0,G24+G33) -> -189.93039 | H38: =-Inputs!$B$55*MAX(0,H24+H33) -> -210.70931 | I38: =-Inputs!$B$55*MAX(0,I24+I33) -> -231.29468 | J38: =-Inputs!$B$55*MAX(0,J24+J33) -> -251.15371 | K38: =-Inputs!$B$55*MAX(0,K24+K33) -> -269.71789 | ... M38: =-Inputs!$B$55*MAX(0,M24+M33) -> -300.66259
A39: Unlevered free cash flow (FCFF) | D39: =D37+D38 -> 154.192 | E39: =E37+E38 -> 328.73475 | F39: =F37+F38 -> 504.58883 | G39: =G37+G38 -> 694.57782 | H39: =H37+H38 -> 776.78344 | I39: =I37+I38 -> 859.08762 | J39: =J37+J38 -> 939.42408 | K39: =K37+K38 -> 1015.5511 | ... M39: =M37+M38 -> 1145.9226
A40: Less: H1 2026 (already in net debt) | D40: =-Inputs!$B$46 -> -75.236 | E40: 0 | F40: 0 | G40: 0 | H40: 0 | I40: 0 | J40: 0 | K40: 0 | L40: 0 | M40: 0
A41: Cash flow to discount | D41: =D39+D40 -> 78.956 | E41: =E39+E40 -> 328.73475 | F41: =F39+F40 -> 504.58883 | G41: =G39+G40 -> 694.57782 | H41: =H39+H40 -> 776.78344 | I41: =I39+I40 -> 859.08762 | J41: =J39+J40 -> 939.42408 | K41: =K39+K40 -> 1015.5511 | ... M41: =M39+M40 -> 1145.9226
A42: Discount factor | D42: =1/(1+Inputs!$B$71)^D8 -> 0.97788941 | E42: =1/(1+Inputs!$B$71)^E8 -> 0.91444792 | F42: =1/(1+Inputs!$B$71)^F8 -> 0.836215 | G42: =1/(1+Inputs!$B$71)^G8 -> 0.76467507 | H42: =1/(1+Inputs!$B$71)^H8 -> 0.69925552 | I42: =1/(1+Inputs!$B$71)^I8 -> 0.63943276 | J42: =1/(1+Inputs!$B$71)^J8 -> 0.58472796 | K42: =1/(1+Inputs!$B$71)^K8 -> 0.53470326 | ... M42: =1/(1+Inputs!$B$71)^M8 -> 0.44712689
A43: Present value | D43: =D41*D42 -> 77.210236 | E43: =E41*E42 -> 300.61081 | F43: =F41*F42 -> 421.94475 | G43: =G41*G42 -> 531.12634 | H43: =H41*H42 -> 543.17011 | I43: =I41*I42 -> 549.32876 | J43: =J41*J42 -> 549.30752 | K43: =K41*K42 -> 543.01848 | ... M43: =M41*M42 -> 512.3728
A45: Valuation
...

Sheet Sensitivity
A1: Base case: value per share (p) by WACC and terminal growth
A2: Each cell re-discounts the base-case cash flows. Rows move WACC around the model's rate; columns move terminal growth.
A4: WACC \ terminal growth | B4: 0.015 | C4: 0.02 | D4: 0.025 | E4: 0.03 | F4: 0.035
A5: =Inputs!$B$71+(-0.01) -> 0.08355599 | B5: =(SUMPRODUCT(DCF_Base!$D$41:$M$41/(1+$A5)^DCF_Base!$D$8:$M$8)+DCF_Base!$M$39*(1+B$4)/($A5-B$4)/(1+$A5)^DCF_Base!$D$50-Inputs!$B$8-Inputs!$B$10-Scenarios!$C$10)/Inputs!$B$6*100 -> 674.69706 | C5: =(SUMPRODUCT(DCF_Base!$D$41:$M$41/(1+$A5)^DCF_Base!$D$8:$M$8)+DCF_Base!$M$39*(1+C$4)/($A5-C$4)/(1+$A5)^DCF_Base!$D$50-Inputs!$B$8-Inputs!$B$10-Scenarios!$C$10)/Inputs!$B$6*100 -> 716.47158 | D5: =(SUMPRODUCT(DCF_Base!$D$41:$M$41/(1+$A5)^DCF_Base!$D$8:$M$8)+DCF_Base!$M$39*(1+D$4)/($A5-D$4)/(1+$A5)^DCF_Base!$D$50-Inputs!$B$8-Inputs!$B$10-Scenarios!$C$10)/Inputs!$B$6*100 -> 765.38022 | E5: =(SUMPRODUCT(DCF_Base!$D$41:$M$41/(1+$A5)^DCF_Base!$D$8:$M$8)+DCF_Base!$M$39*(1+E$4)/($A5-E$4)/(1+$A5)^DCF_Base!$D$50-Inputs!$B$8-Inputs!$B$10-Scenarios!$C$10)/Inputs!$B$6*100 -> 823.42111 | F5: =(SUMPRODUCT(DCF_Base!$D$41:$M$41/(1+$A5)^DCF_Base!$D$8:$M$8)+DCF_Base!$M$39*(1+F$4)/($A5-F$4)/(1+$A5)^DCF_Base!$D$50-Inputs!$B$8-Inputs!$B$10-Scenarios!$C$10)/Inputs!$B$6*100 -> 893.41539
A6: =Inputs!$B$71+(-0.005) -> 0.08855599 | B6: =(SUMPRODUCT(DCF_Base!$D$41:$M$41/(1+$A6)^DCF_Base!$D$8:$M$8)+DCF_Base!$M$39*(1+B$4)/($A6-B$4)/(1+$A6)^DCF_Base!$D$50-Inputs!$B$8-Inputs!$B$10-Scenarios!$C$10)/Inputs!$B$6*100 -> 613.80651 | C6: =(SUMPRODUCT(DCF_Base!$D$41:$M$41/(1+$A6)^DCF_Base!$D$8:$M$8)+DCF_Base!$M$39*(1+C$4)/($A6-C$4)/(1+$A6)^DCF_Base!$D$50-Inputs!$B$8-Inputs!$B$10-Scenarios!$C$10)/Inputs!$B$6*100 -> 648.51654 | D6: =(SUMPRODUCT(DCF_Base!$D$41:$M$41/(1+$A6)^DCF_Base!$D$8:$M$8)+DCF_Base!$M$39*(1+D$4)/($A6-D$4)/(1+$A6)^DCF_Base!$D$50-Inputs!$B$8-Inputs!$B$10-Scenarios!$C$10)/Inputs!$B$6*100 -> 688.68789 | E6: =(SUMPRODUCT(DCF_Base!$D$41:$M$41/(1+$A6)^DCF_Base!$D$8:$M$8)+DCF_Base!$M$39*(1+E$4)/($A6-E$4)/(1+$A6)^DCF_Base!$D$50-Inputs!$B$8-Inputs!$B$10-Scenarios!$C$10)/Inputs!$B$6*100 -> 735.71958 | F6: =(SUMPRODUCT(DCF_Base!$D$41:$M$41/(1+$A6)^DCF_Base!$D$8:$M$8)+DCF_Base!$M$39*(1+F$4)/($A6-F$4)/(1+$A6)^DCF_Base!$D$50-Inputs!$B$8-Inputs!$B$10-Scenarios!$C$10)/Inputs!$B$6*100 -> 791.53305
A7: =Inputs!$B$71+(0) -> 0.09355599 | B7: =(SUMPRODUCT(DCF_Base!$D$41:$M$41/(1+$A7)^DCF_Base!$D$8:$M$8)+DCF_Base!$M$39*(1+B$4)/($A7-B$4)/(1+$A7)^DCF_Base!$D$50-Inputs!$B$8-Inputs!$B$10-Scenarios!$C$10)/Inputs!$B$6*100 -> 560.86119 | C7: =(SUMPRODUCT(DCF_Base!$D$41:$M$41/(1+$A7)^DCF_Base!$D$8:$M$8)+DCF_Base!$M$39*(1+C$4)/($A7-C$4)/(1+$A7)^DCF_Base!$D$50-Inputs!$B$8-Inputs!$B$10-Scenarios!$C$10)/Inputs!$B$6*100 -> 589.99544 | D7: =(SUMPRODUCT(DCF_Base!$D$41:$M$41/(1+$A7)^DCF_Base!$D$8:$M$8)+DCF_Base!$M$39*(1+D$4)/($A7-D$4)/(1+$A7)^DCF_Base!$D$50-Inputs!$B$8-Inputs!$B$10-Scenarios!$C$10)/Inputs!$B$6*100 -> 623.3794 | E7: =(SUMPRODUCT(DCF_Base!$D$41:$M$41/(1+$A7)^DCF_Base!$D$8:$M$8)+DCF_Base!$M$39*(1+E$4)/($A7-E$4)/(1+$A7)^DCF_Base!$D$50-Inputs!$B$8-Inputs!$B$10-Scenarios!$C$10)/Inputs!$B$6*100 -> 662.01603 | F7: =(SUMPRODUCT(DCF_Base!$D$41:$M$41/(1+$A7)^DCF_Base!$D$8:$M$8)+DCF_Base!$M$39*(1+F$4)/($A7-F$4)/(1+$A7)^DCF_Base!$D$50-Inputs!$B$8-Inputs!$B$10-Scenarios!$C$10)/Inputs!$B$6*100 -> 707.25091
A8: =Inputs!$B$71+(0.005) -> 0.09855599 | B8: =(SUMPRODUCT(DCF_Base!$D$41:$M$41/(1+$A8)^DCF_Base!$D$8:$M$8)+DCF_Base!$M$39*(1+B$4)/($A8-B$4)/(1+$A8)^DCF_Base!$D$50-Inputs!$B$8-Inputs!$B$10-Scenarios!$C$10)/Inputs!$B$6*100 -> 514.42607 | C8: =(SUMPRODUCT(DCF_Base!$D$41:$M$41/(1+$A8)^DCF_Base!$D$8:$M$8)+DCF_Base!$M$39*(1+C$4)/($A8-C$4)/(1+$A8)^DCF_Base!$D$50-Inputs!$B$8-Inputs!$B$10-Scenarios!$C$10)/Inputs!$B$6*100 -> 539.09808 | D8: =(SUMPRODUCT(DCF_Base!$D$41:$M$41/(1+$A8)^DCF_Base!$D$8:$M$8)+DCF_Base!$M$39*(1+D$4)/($A8-D$4)/(1+$A8)^DCF_Base!$D$50-Inputs!$B$8-Inputs!$B$10-Scenarios!$C$10)/Inputs!$B$6*100 -> 567.12426 | E8: =(SUMPRODUCT(DCF_Base!$D$41:$M$41/(1+$A8)^DCF_Base!$D$8:$M$8)+DCF_Base!$M$39*(1+E$4)/($A8-E$4)/(1+$A8)^DCF_Base!$D$50-Inputs!$B$8-Inputs!$B$10-Scenarios!$C$10)/Inputs!$B$6*100 -> 599.23851 | F8: =(SUMPRODUCT(DCF_Base!$D$41:$M$41/(1+$A8)^DCF_Base!$D$8:$M$8)+DCF_Base!$M$39*(1+F$4)/($A8-F$4)/(1+$A8)^DCF_Base!$D$50-Inputs!$B$8-Inputs!$B$10-Scenarios!$C$10)/Inputs!$B$6*100 -> 636.40567
A9: =Inputs!$B$71+(0.01) -> 0.10355599 | B9: =(SUMPRODUCT(DCF_Base!$D$41:$M$41/(1+$A9)^DCF_Base!$D$8:$M$8)+DCF_Base!$M$39*(1+B$4)/($A9-B$4)/(1+$A9)^DCF_Base!$D$50-Inputs!$B$8-Inputs!$B$10-Scenarios!$C$10)/Inputs!$B$6*100 -> 473.39073 | C9: =(SUMPRODUCT(DCF_Base!$D$41:$M$41/(1+$A9)^DCF_Base!$D$8:$M$8)+DCF_Base!$M$39*(1+C$4)/($A9-C$4)/(1+$A9)^DCF_Base!$D$50-Inputs!$B$8-Inputs!$B$10-Scenarios!$C$10)/Inputs!$B$6*100 -> 494.448 | D9: =(SUMPRODUCT(DCF_Base!$D$41:$M$41/(1+$A9)^DCF_Base!$D$8:$M$8)+DCF_Base!$M$39*(1+D$4)/($A9-D$4)/(1+$A9)^DCF_Base!$D$50-Inputs!$B$8-Inputs!$B$10-Scenarios!$C$10)/Inputs!$B$6*100 -> 518.18583 | E9: =(SUMPRODUCT(DCF_Base!$D$41:$M$41/(1+$A9)^DCF_Base!$D$8:$M$8)+DCF_Base!$M$39*(1+E$4)/($A9-E$4)/(1+$A9)^DCF_Base!$D$50-Inputs!$B$8-Inputs!$B$10-Scenarios!$C$10)/Inputs!$B$6*100 -> 545.15083 | F9: =(SUMPRODUCT(DCF_Base!$D$41:$M$41/(1+$A9)^DCF_Base!$D$8:$M$8)+DCF_Base!$M$39*(1+F$4)/($A9-F$4)/(1+$A9)^DCF_Base!$D$50-Inputs!$B$8-Inputs!$B$10-Scenarios!$C$10)/Inputs!$B$6*100 -> 576.04911
A11: Share price | B11: =Inputs!$B$5 -> 450
A12: Cells above the share price | B12: =COUNTIF(B5:F9,">"&B11)&" of 25" -> 25 of 25

Sheet Comps
A1: Cross-checks: peer multiples and a recent takeover
A2: Consensus adjusted EPS from S&P Global via stockanalysis.com. Prices are the latest on the page as of 6-8 Oct 2026.
A4: Company | B4: Ticker | C4: Currency | D4: Share price | E4: Price date | F4: EPS 2026E | G4: P/E 2026E | H4: Notes
A5: Rolls-Royce | B5: RR.L | C5: pence | D5: 1369.8 | E5: 8 Oct 2026 | F5: 44 | G5: =D5/F5 -> 31.131818 | H5: Engines; services earned per flying hour
A6: Safran | B6: SAF.PA | C6: EUR | D6: 328.9 | E6: 6 Oct 2026 | F6: 10.42 | G6: =D6/F6 -> 31.564299 | H6: Engines (CFM with GE) and equipment
A7: MTU Aero Engines | B7: MTX.DE | C7: EUR | D7: 367.1 | E7: 6 Oct 2026 | F7: 18.98 | G7: =D7/F7 -> 19.341412 | H7: Engine parts partner, like GKN's RRSP model
A8: GE Aerospace | B8: GE | C8: USD | D8: 303.62 | E8: 7 Oct 2026 | F8: 7.92 | G8: =D8/F8 -> 38.335859 | H8: Engines (LEAP, GEnx, GE9X)
A9: Howmet Aerospace | B9: HWM | C9: USD | D9: 231.6 | E9: 6 Oct 2026 | F9: 5.34 | G9: =D9/F9 -> 43.370787 | H9: Engine and airframe components
A10: Peer median | G10: =MEDIAN(G5:G9) -> 31.564299
A11: Melrose | B11: MRO.L | C11: pence | D11: =Inputs!$B$5 -> 450 | E11: 7 Oct 2026 | F11: =Inputs!$B$14 -> 35 | G11: =D11/F11 -> 12.857143
A12: Melrose discount to peer median | G12: =1-G11/G10 -> 0.5926682
A13: Melrose EPS excluding non-cash VC | F13: =F11-Inputs!$B$25*(1-Inputs!$B$55)/Inputs!$B$6*100 -> 12.001605 | G13: =D11/F13 -> 37.494985 | H13: On cash-backed earnings Melrose is not cheap: the debate is when VC turns into cash
A15: Takeover cross-check: Senior plc (UK aerospace and defence parts maker)
A16: Senior plc: EV / FY2025 adjusted EBITDA agreed | G16: 15.2 | H16: Blackstone/Tinicum offer, Rule 2.7 announcement, 7 Apr 2026 (300p a share, EV ~£1,399m)
A17: Melrose FY2025 adjusted EBITDA | G17: =DCF_Base!C28 -> 785 | H17: Adjusted operating profit £647m + D&A £138m
A18: of which non-cash VC | G18: =-DCF_Base!C33 -> 324 | H18: FY2025 results
A19: Melrose FY2025 EBITDA excluding VC | G19: =G17-G18 -> 461 | H19: Formula
A20: Melrose EV / EBITDA | G20: =Inputs!$B$11/G17 -> 9.5261146 | H20: EV includes leases, matching EBITDA
A21: Melrose EV / EBITDA excluding VC | G21: =Inputs!$B$11/G19 -> 16.221258 | H21: Close to the multiple agreed for Senior
A22: Value at Senior's multiple, VC worth nothing | G22: =(G16*G19-(Inputs!$B$8+Inputs!$B$9+Inputs!$B$10+Scenarios!$C$10))/Inputs!$B$6*100 -> 402.58427 | H22: Applies 15.2x to cash EBITDA only
A23: Value at Senior's multiple, VC worth full value | G23: =(G16*G17-(Inputs!$B$8+Inputs!$B$9+Inputs!$B$10+Scenarios!$C$10))/Inputs!$B$6*100 -> 797.83307 | H23: Applies 15.2x to all EBITDA

Sheet History
A1: Reported figures
A2: FY2024-25 from the FY2025 results (27 Feb 2026); half years from the H1 2026 results (31 Jul 2026). £m unless stated.
A4: Item | B4: FY2024 | C4: FY2025 | D4: H1 2025 | E4: H1 2026
A5: Engines revenue | B5: 1459 | C5: 1632 | D5: 781 | E5: 896
A6: Airframes revenue | B6: 2009 | C6: 1957 | D6: 939 | E6: 977
A7: Group revenue | B7: =B5+B6 -> 3468 | C7: =C5+C6 -> 3589 | D7: =D5+D6 -> 1720 | E7: =E5+E6 -> 1873
A8: Engines adjusted operating profit | B8: 422 | C8: 520 | D8: 261 | E8: 303
A9: Airframes adjusted operating profit | B9: 144 | C9: 156 | D9: 63 | E9: 62
A10: Central costs | B10: -26 | C10: -29 | D10: -14 | E10: -18
A11: Group adjusted operating profit | B11: =B8+B9+B10 -> 540 | C11: =C8+C9+C10 -> 647 | D11: =D8+D9+D10 -> 310 | E11: =E8+E9+E10 -> 347
A12: Engines margin | B12: =B8/B5 -> 0.2892392 | C12: =C8/C5 -> 0.31862745 | D12: =D8/D5 -> 0.33418694 | E12: =E8/E5 -> 0.33816964
A13: Airframes margin | B13: =B9/B6 -> 0.071677451 | C13: =C9/C6 -> 0.079713848 | D13: =D9/D6 -> 0.067092652 | E13: =E9/E6 -> 0.06345957
A14: Group margin | B14: =B11/B7 -> 0.15570934 | C14: =C11/C7 -> 0.18027306 | D14: =D11/D7 -> 0.18023256 | E14: =E11/E7 -> 0.18526428
A15: Variable consideration in profit (non-cash) | B15: 274 | C15: 324 | D15: 182 | E15: 206
A16: VC as % of group profit | B16: =B15/B11 -> 0.50740741 | C16: =C15/C11 -> 0.5007728 | D16: =D15/D11 -> 0.58709677 | E16: =E15/E11 -> 0.59365994
A17: Free cash flow (after interest and tax) | B17: -74 | C17: 125 | D17: -54 | E17: 13
A18: Net debt (excluding leases) | B18: 1321 | C18: 1407 | E18: 1530
A19: Shares in issue excluding treasury (m) | B19: 1286 | C19: 1258 | E19: 1246
A20: Adjusted diluted EPS (p) | B20: 26.4 | C20: 32.1 | D20: 15.1 | E20: 17.7
A21: Dividend per share (p) | B21: 6 | C21: 7.2 | D21: 2.4 | E21: 2.7
A23: Central costs are group profit less the two divisions. H1 dividend is the interim.
